Backup failed for Site erp.localhost. Database or site_config.json may be corrupted
Traceback with variables (most recent call last):
  File "apps/frappe/frappe/commands/site.py", line 837, in backup
    odb = scheduled_backup(
      context = {'sites': ['erp.localhost'], 'force': False, 'verbose': True, 'profile': False}
      with_files = False
      backup_path = None
      backup_path_db = None
      backup_path_files = None
      backup_path_private_files = None
      backup_path_conf = None
      ignore_backup_conf = False
      verbose = True
      compress = False
      include = ''
      exclude = ''
      old_backup_metadata = False
      scheduled_backup = <function scheduled_backup at 0x107e131a0>
      exit_code = 0
      rollback_callback = None
      site = 'erp.localhost'
  File "apps/frappe/frappe/utils/backups.py", line 577, in scheduled_backup
    return new_backup(
      older_than = 6
      ignore_files = True
      backup_path = None
      backup_path_db = None
      backup_path_files = None
      backup_path_private_files = None
      backup_path_conf = None
      ignore_conf = False
      include_doctypes = ''
      exclude_doctypes = ''
      compress = False
      force = True
      verbose = True
      old_backup_metadata = False
      rollback_callback = <frappe.utils.CallbackManager object at 0x107fb1d50>
  File "apps/frappe/frappe/utils/backups.py", line 635, in new_backup
    odb.get_backup(older_than, ignore_files, force=force)
      older_than = 6
      ignore_files = True
      backup_path = None
      backup_path_db = None
      backup_path_files = None
      backup_path_private_files = None
      backup_path_conf = None
      ignore_conf = False
      include_doctypes = ''
      exclude_doctypes = ''
      compress = False
      force = True
      verbose = True
      old_backup_metadata = False
      rollback_callback = <frappe.utils.CallbackManager object at 0x107fb1d50>
      odb = <frappe.utils.backups.BackupGenerator object at 0x107eb5b50>
  File "apps/frappe/frappe/utils/backups.py", line 191, in get_backup
    self.delete_if_step_fails(self.take_dump, self.backup_path_db)
      self = <frappe.utils.backups.BackupGenerator object at 0x107eb5b50>
      older_than = 6
      ignore_files = True
      force = True
      last_db = False
      last_file = False
      last_private_file = False
      site_config_backup_path = False
  File "apps/frappe/frappe/utils/backups.py", line 516, in delete_if_step_fails
    raise e
      self = <frappe.utils.backups.BackupGenerator object at 0x107eb5b50>
      step = <bound method BackupGenerator.take_dump of <frappe.utils.backups.BackupGenerator object at 0x107eb5b50>>
      paths = ('./erp.localhost/private/backups/20240616_003002-erp_localhost-database.sql.gz',)
      path = './erp.localhost/private/backups/20240616_003002-erp_localhost-database.sql.gz'
  File "apps/frappe/frappe/utils/backups.py", line 511, in delete_if_step_fails
    step()
      self = <frappe.utils.backups.BackupGenerator object at 0x107eb5b50>
      step = <bound method BackupGenerator.take_dump of <frappe.utils.backups.BackupGenerator object at 0x107eb5b50>>
      paths = ('./erp.localhost/private/backups/20240616_003002-erp_localhost-database.sql.gz',)
      path = './erp.localhost/private/backups/20240616_003002-erp_localhost-database.sql.gz'
  File "apps/frappe/frappe/utils/backups.py", line 453, in take_dump
    frappe.throw(
      self = <frappe.utils.backups.BackupGenerator object at 0x107eb5b50>
      shlex = <module 'shlex' from '/opt/homebrew/Cellar/python@3.12/3.12.2_1/Frameworks/Python.framework/Versions/3.12/lib/python3.12/shlex.py'>
      frappe = <module 'frappe' from 'apps/frappe/frappe/__init__.py'>
      get_app_branch = <function get_app_branch at 0x1041065c0>
      gzip_exc = '/usr/bin/gzip'
      database_header_content = ['begin frappe metadata', '[frappe]', 'version = 16.0.0-dev', 'branch = develop', 'end frappe metadata', '']
      generated_header = '-- begin frappe metadata\n-- [frappe]\n-- version = 16.0.0-dev\n-- branch = develop\n-- end frappe metadata\n-- \n'
      f = <_io.TextIOWrapper name='./erp.localhost/private/backups/20240616_003002-erp_localhost-database.sql.gz' encoding='UTF-8'>
      cmd = []
      extra = []
      get_command = <function get_command at 0x107e5de40>
      bin = None
      args = ['--user=_623e70aabf118c9e', '--host=127.0.0.1', '--port=3306', '--password=87W0IypTH0Zt0lXl', '--single-transaction', '--quick', '--lock-tables=false', '_623e70aabf118c9e']
      bin_name = 'mariadb-dump'
  File "apps/frappe/frappe/__init__.py", line 681, in throw
    msgprint(
      msg = 'mariadb-dump not found in PATH! This is required to take a backup.'
      exc = <class 'frappe.exceptions.ExecutableNotFound'>
      title = None
      is_minimizable = False
      wide = False
      as_list = False
      primary_action = None
  File "apps/frappe/frappe/__init__.py", line 646, in msgprint
    _raise_exception()
      msg = 'mariadb-dump not found in PATH! This is required to take a backup.'
      title = None
      raise_exception = <class 'frappe.exceptions.ExecutableNotFound'>
      as_table = False
      as_list = False
      indicator = 'red'
      alert = False
      primary_action = None
      is_minimizable = False
      wide = False
      realtime = False
      _raise_exception = <function msgprint.<locals>._raise_exception at 0x1040b23e0>
      inspect = <module 'inspect' from '/opt/homebrew/Cellar/python@3.12/3.12.2_1/Frameworks/Python.framework/Versions/3.12/lib/python3.12/inspect.py'>
      out = {'message': 'mariadb-dump not found in PATH! This is required to take a backup.', 'title': 'Message', 'indicator': 'red', 'raise_exception': 1, '__frappe_exc_id': 'ca769bdd0c73d3ffadf9daed332682d18ae64d35ad6486b7eb217390'}
  File "apps/frappe/frappe/__init__.py", line 597, in _raise_exception
    raise exc
      exc = ExecutableNotFound('mariadb-dump not found in PATH! This is required to take a backup.')
      inspect = <module 'inspect' from '/opt/homebrew/Cellar/python@3.12/3.12.2_1/Frameworks/Python.framework/Versions/3.12/lib/python3.12/inspect.py'>
      msg = 'mariadb-dump not found in PATH! This is required to take a backup.'
      out = {'message': 'mariadb-dump not found in PATH! This is required to take a backup.', 'title': 'Message', 'indicator': 'red', 'raise_exception': 1, '__frappe_exc_id': 'ca769bdd0c73d3ffadf9daed332682d18ae64d35ad6486b7eb217390'}
      raise_exception = <class 'frappe.exceptions.ExecutableNotFound'>
frappe.exceptions.ExecutableNotFound: mariadb-dump not found in PATH! This is required to take a backup.
